Workbook

Sheet AUCROC Weight
B1: Sector | D1: Corporate | V1: Households | AI1: Government | AX1: Banking | BM1: External | BZ1: Недвижимость
B2: Indicator | D2: Debt service ratio, % | I2: All Debt to GDP ratio, % | N2: Прирост реального кредита банков ЮЛ (дефлятор ВВП 2018=1) | Q2: Складские запасы в промышленности к среднемесячному ОПП, % | V2: Debt_service ratio_annual | AA2: Кредит ФЛ к ВВП | AF2: Прирост реального кредита банков ФЛ (ИПЦ 2018=1) | AI2: Обслуживание внешнего долга органов государственного управления к ВВП, % | AN2: Отношение сальдо консолидированного бюджета к ВВП, % | AS2: Долг сектора государственного управления к ВВП, % (внешний + внутренний) | AX2: Требования банков к экономике к ВВП, % | BC2: Требования банков к депозитам банков, % | BH2: Леверидж (активы к собственному капиталу), раз | BM2: Счет текущих операций за год, в % к ВВП | BR2: Валовый внешний долг к ВВП | BW2: Логарифм цен на коммерческую недвижимость, скорректированных на дефлятор, *100 | CB2: Логарифм цен на жилую недвижимость, скорректированных на ИПЦ
D3: dsr | E3: dsr1 | F3: dsr2 | G3: dsr_av2 | H3: dsr_av3 | I3: ggr | J3: ggr1 | K3: ggr2 | L3: ggr_av2 | M3: ggr_av3 | N3: rcgr_c1 | O3: rcgr_c2 | P3: rcgr_c3 | Q3: invr | R3: invr1 | S3: invr2 | T3: invr_av2 | U3: invr_av3 | V3: d_srv | W3: d_srv1 | X3: d_srv2 | Y3: d_srv_av2 | Z3: d_srv_av3 | AA3: l_gdp | AB3: l_gdp1 | AC3: l_gdp2 | AD3: l_gdp_av2 | AE3: l_gdp_av3 | AF3: rcgr_h1 | AG3: rcgr_h2 | AH3: rcgr_h3 | AI3: exd_s | AJ3: exd_s1 | AK3: exd_s2 | AL3: exd_s_av2 | AM3: exd_s_av3 | AN3: bb_gdp | AO3: bb_gdp1 | AP3: bb_gdp2 | AQ3: bb_gdp_av2 | AR3: bb_gdp_av3 | AS3: ggd | AT3: ggd1 | AU3: ggd2 | AV3: ggd_av2 | AW3: ggd_av3 | AX3: crr | AY3: crr1 | AZ3: crr2 | BA3: crr_av2 | BB3: crr_av3 | BC3: d_as | BD3: d_as1 | BE3: d_as2 | BF3: d_as_av2 | BG3: d_as_av3 | BH3: lvr | BI3: lvr1 | BJ3: lvr2 | BK3: lvr_av2 | BL3: lvr_av3 | BM3: ca | BN3: ca1 | BO3: ca2 | BP3: ca_av2 | BQ3: ca_av3 | BR3: gd_gdp | BS3: gd_gdp1 | BT3: gd_gdp2 | BU3: gd_gdp_av2 | BV3: gd_gdp_av3 | BW3: cest | BX3: cest1 | BY3: cest2 | BZ3: cest_av2 | CA3: cest_av3 | CB3: pest | CC3: pest1 | CD3: pest2 | CE3: pest_av2 | CF3: pest_av3
C4: 12 | D4: 0.48846154 | E4: 0.65053763 | F4: 0.74712644 | G4: 0.74137931 | H4: 0.67272727 | I4: 0.56617647 | J4: 0.6171875 | K4: 0.50273224 | L4: 0.53005464 | M4: 0.54385965 | N4: 0.72426471 | O4: 0.65441176 | P4: 0.70522388 | Q4: 0.76102941 | R4: 0.58203125 | S4: 0.72131148 | T4: 0.59016393 | U4: 0.62573099 | V4: 0.5546875 | W4: 0.6010929 | X4: 0.57309942 | Y4: 0.59064327 | Z4: 0.52777778 | AA4: 0.50367647 | AB4: 0.69921875 | AC4: 0.45901639 | AD4: 0.63387978 | AE4: 0.58479532 | AF4: 0.59191176 | AG4: 0.51838235 | AH4: 0.49626866 | AI4: 0.65441176 | AJ4: 0.66015625 | AK4: 0.4863388 | AL4: 0.54644809 | AM4: 0.58479532 | AN4: 0.69117647 | AO4: 0.49609375 | AP4: 0.87431694 | AQ4: 0.72677596 | AR4: 0.81871345 | AS4: 0.50367647 | AT4: 0.53515625 | AU4: 0.57923497 | AV4: 0.53551913 | AW4: 0.5380117 | AX4: 0.54411765 | AY4: 0.70703125 | AZ4: 0.47540984 | BA4: 0.59016393 | BB4: 0.50877193 | BC4: 0.56985294 | BD4: 0.66015625 | BE4: 0.46994536 | BF4: 0.6010929 | BG4: 0.55555556 | BH4: 0.45895522 | BI4: 0.76041667 | BJ4: 0.73888889 | BK4: 0.75 | BL4: 0.77380952 | BM4: 0.56617647 | BN4: 0.7109375 | BO4: 0.55737705 | BP4: 0.66120219 | BQ4: 0.61403509 | BR4: 0.52941176 | BS4: 0.55078125 | BT4: 0.61748634 | BU4: 0.55737705 | BV4: 0.57309942 | BW4: 0.73461538 | BX4: 0.65591398 | BY4: 0.52873563 | BZ4: 0.63218391 | CA4: 0.66363636 | CB4: 0.61458333 | CC4: 0.82222222 | CD4: 0.625 | CE4: 0.83928571 | CF4: 0.5
C5: 11 | D5: 0.57954545 | E5: 0.54497354 | F5: 0.65536723 | G5: 0.53107345 | H5: 0.49107143 | I5: 0.67028986 | J5: 0.68846154 | K5: 0.60752688 | L5: 0.65053763 | M5: 0.61494253 | N5: 0.71014493 | O5: 0.66666667 | P5: 0.70955882 | Q5: 0.76630435 | R5: 0.61923077 | S5: 0.6827957 | T5: 0.59139785 | U5: 0.6954023 | V5: 0.53846154 | W5: 0.53225806 | X5: 0.57471264 | Y5: 0.57471264 | Z5: 0.5 | AA5: 0.61594203 | AB5: 0.67307692 | AC5: 0.56451613 | AD5: 0.63978495 | AE5: 0.5862069 | AF5: 0.54710145 | AG5: 0.51086957 | AH5: 0.54779412 | AI5: 0.68115942 | AJ5: 0.64615385 | AK5: 0.47849462 | AL5: 0.58602151 | AM5: 0.56321839 | AN5: 0.72463768 | AO5: 0.46538462 | AP5: 0.84946237 | AQ5: 0.72580645 | AR5: 0.82758621 | AS5: 0.60869565 | AT5: 0.50769231 | AU5: 0.64516129 | AV5: 0.61827957 | AW5: 0.63218391 | AX5: 0.66666667 | AY5: 0.71153846 | AZ5: 0.66129032 | BA5: 0.69354839 | BB5: 0.6954023 | BC5: 0.5326087 | BD5: 0.61923077 | BE5: 0.54301075 | BF5: 0.55376344 | BG5: 0.53448276 | BH5: 0.55514706 | BI5: 0.54296875 | BJ5: 0.67213115 | BK5: 0.5136612 | BL5: 0.59064327 | BM5: 0.57246377 | BN5: 0.6 | BO5: 0.5483871 | BP5: 0.62365591 | BQ5: 0.56896552 | BR5: 0.58333333 | BS5: 0.55384615 | BT5: 0.60215054 | BU5: 0.55376344 | BV5: 0.56896552 | BW5: 0.64015152 | BX5: 0.5978836 | BY5: 0.66666667 | BZ5: 0.54237288 | CA5: 0.58035714 | CB5: 0.48828125 | CC5: 0.7431694 | CD5: 0.78947368 | CE5: 0.92982456 | CF5: 0.66666667
C6: 10 | D6: 0.62313433 | E6: 0.70833333 | F6: 0.50555556 | G6: 0.67222222 | H6: 0.52380952 | I6: 0.81428571 | J6: 0.76515152 | K6: 0.72486772 | L6: 0.7989418 | M6: 0.74576271 | N6: 0.59285714 | O6: 0.70714286 | P6: 0.68478261 | Q6: 0.78928571 | R6: 0.48863636 | S6: 0.58201058 | T6: 0.57142857 | U6: 0.64971751 | V6: 0.54924242 | W6: 0.47089947 | X6: 0.56497175 | Y6: 0.57062147 | Z6: 0.5 | AA6: 0.53928571 | AB6: 0.56818182 | AC6: 0.56084656 | AD6: 0.57671958 | AE6: 0.5480226 | AF6: 0.47857143 | AG6: 0.50357143 | AH6: 0.60507246 | AI6: 0.65357143 | AJ6: 0.56818182 | AK6: 0.53968254 | AL6: 0.52380952 | AM6: 0.50282486 | AN6: 0.7 | AO6: 0.52272727 | AP6: 0.6031746 | AQ6: 0.55026455 | AR6: 0.71186441 | AS6: 0.65714286 | AT6: 0.5719697 | AU6: 0.7037037 | AV6: 0.65608466 | AW6: 0.72316384 | AX6: 0.78214286 | AY6: 0.67424242 | AZ6: 0.71957672 | BA6: 0.73015873 | BB6: 0.6779661 | BC6: 0.50357143 | BD6: 0.53030303 | BE6: 0.51322751 | BF6: 0.52910053 | BG6: 0.52542373 | BH6: 0.7173913 | BI6: 0.6 | BJ6: 0.5483871 | BK6: 0.67204301 | BL6: 0.55747126 | BM6: 0.60714286 | BN6: 0.5530303 | BO6: 0.5978836 | BP6: 0.6031746 | BQ6: 0.5480226 | BR6: 0.65 | BS6: 0.54166667 | BT6: 0.62962963 | BU6: 0.64021164 | BV6: 0.63841808 | BW6: 0.64925373 | BX6: 0.5625 | BY6: 0.58333333 | BZ6: 0.56111111 | CA6: 0.46428571 | CB6: 0.53461538 | CC6: 0.56989247 | CD6: 0.8045977 | CE6: 0.6954023 | CF6: 0.7
C7: 9 | D7: 0.70955882 | E7: 0.8359375 | F7: 0.59562842 | G7: 0.81967213 | H7: 0.66666667 | I7: 0.71478873 | J7: 0.6119403 | K7: 0.69791667 | L7: 0.671875 | M7: 0.67222222 | N7: 0.59507042 | O7: 0.53169014 | P7: 0.525 | Q7: 0.58450704 | R7: 0.69776119 | S7: 0.61979167 | T7: 0.71354167 | U7: 0.59444444 | V7: 0.58955224 | W7: 0.44270833 | X7: 0.58333333 | Y7: 0.57222222 | Z7: 0.5952381 | AA7: 0.45070423 | AB7: 0.45895522 | AC7: 0.515625 | AD7: 0.47916667 | AE7: 0.46111111 | AF7: 0.44014085 | AG7: 0.50352113 | AH7: 0.6 | AI7: 0.66197183 | AJ7: 0.62313433 | AK7: 0.53645833 | AL7: 0.60416667 | AM7: 0.51666667 | AN7: 0.69366197 | AO7: 0.53358209 | AP7: 0.53125 | AQ7: 0.59895833 | AR7: 0.53888889 | AS7: 0.58802817 | AT7: 0.51119403 | AU7: 0.63020833 | AV7: 0.55208333 | AW7: 0.65555556 | AX7: 0.6443662 | AY7: 0.55970149 | AZ7: 0.63541667 | BA7: 0.59895833 | BB7: 0.58888889 | BC7: 0.56338028 | BD7: 0.46641791 | BE7: 0.52604167 | BF7: 0.52604167 | BG7: 0.49444444 | BH7: 0.725 | BI7: 0.67045455 | BJ7: 0.58730159 | BK7: 0.77777778 | BL7: 0.63276836 | BM7: 0.54577465 | BN7: 0.64552239 | BO7: 0.51041667 | BP7: 0.47916667 | BQ7: 0.45555556 | BR7: 0.6971831 | BS7: 0.57089552 | BT7: 0.64583333 | BU7: 0.63020833 | BV7: 0.66666667 | BW7: 0.82720588 | BX7: 0.8359375 | BY7: 0.71584699 | BZ7: 0.8852459 | CA7: 0.80701754 | CB7: 0.54166667 | CC7: 0.53968254 | CD7: 0.81355932 | CE7: 0.61016949 | CF7: 0.66071429
C8: 8 | D8: 0.71014493 | E8: 0.82692308 | F8: 0.6827957 | G8: 0.82258065 | H8: 0.6954023 | I8: 0.53819444 | J8: 0.41911765 | K8: 0.578125 | L8: 0.43359375 | M8: 0.53005464 | N8: 0.73958333 | O8: 0.50694444 | P8: 0.54225352 | Q8: 0.59027778 | R8: 0.77941176 | S8: 0.69335938 | T8: 0.7578125 | U8: 0.73770492 | V8: 0.58455882 | W8: 0.62890625 | X8: 0.61202186 | Y8: 0.61202186 | Z8: 0.60818713 | AA8: 0.43055556 | AB8: 0.41911765 | AC8: 0.515625 | AD8: 0.43359375 | AE8: 0.3989071 | AF8: 0.64236111 | AG8: 0.51041667 | AH8: 0.61267606 | AI8: 0.66666667 | AJ8: 0.54044118 | AK8: 0.66796875 | AL8: 0.62109375 | AM8: 0.46448087 | AN8: 0.56597222 | AO8: 0.66176471 | AP8: 0.53125 | AQ8: 0.64453125 | AR8: 0.71584699 | AS8: 0.66319444 | AT8: 0.57352941 | AU8: 0.59375 | AV8: 0.58203125 | AW8: 0.63934426 | AX8: 0.5 | AY8: 0.45588235 | AZ8: 0.59765625 | BA8: 0.48046875 | BB8: 0.53551913 | BC8: 0.49305556 | BD8: 0.57352941 | BE8: 0.48828125 | BF8: 0.56640625 | BG8: 0.48087432 | BH8: 0.62323944 | BI8: 0.62313433 | BJ8: 0.515625 | BK8: 0.63020833 | BL8: 0.5 | BM8: 0.63194444 | BN8: 0.66911765 | BO8: 0.4453125 | BP8: 0.65625 | BQ8: 0.57923497 | BR8: 0.6875 | BS8: 0.61029412 | BT8: 0.66796875 | BU8: 0.62890625 | BV8: 0.66666667 | BW8: 0.7826087 | BX8: 0.83076923 | BY8: 0.68817204 | BZ8: 0.80107527 | CA8: 0.79885057 | CB8: 0.5261194 | CC8: 0.609375 | CD8: 0.65 | CE8: 0.48333333 | CF8: 0.64285714
C9: 7 | D9: 0.68571429 | E9: 0.59848485 | F9: 0.68253968 | G9: 0.75132275 | H9: 0.63841808 | I9: 0.52054795 | J9: 0.67391304 | K9: 0.47692308 | L9: 0.62692308 | M9: 0.58064516 | N9: 0.85958904 | O9: 0.6369863 | P9: 0.61111111 | Q9: 0.76712329 | R9: 0.87318841 | S9: 0.76153846 | T9: 0.9 | U9: 0.91397849 | V9: 0.48913043 | W9: 0.66923077 | X9: 0.62365591 | Y9: 0.60752688 | Z9: 0.63793103 | AA9: 0.56164384 | AB9: 0.59057971 | AC9: 0.5 | AD9: 0.46538462 | AE9: 0.40860215 | AF9: 0.6130137 | AG9: 0.5239726 | AH9: 0.58680556 | AI9: 0.62671233 | AJ9: 0.60144928 | AK9: 0.58846154 | AL9: 0.52307692 | AM9: 0.53225806 | AN9: 0.63356164 | AO9: 0.73188406 | AP9: 0.72307692 | AQ9: 0.72307692 | AR9: 0.83333333 | AS9: 0.65410959 | AT9: 0.52173913 | AU9: 0.56153846 | AV9: 0.55769231 | AW9: 0.56451613 | AX9: 0.45547945 | AY9: 0.64855072 | AZ9: 0.51538462 | BA9: 0.60769231 | BB9: 0.53763441 | BC9: 0.65068493 | BD9: 0.69927536 | BE9: 0.45384615 | BF9: 0.62692308 | BG9: 0.56451613 | BH9: 0.55555556 | BI9: 0.52573529 | BJ9: 0.58203125 | BK9: 0.51953125 | BL9: 0.53551913 | BM9: 0.69178082 | BN9: 0.82608696 | BO9: 0.57692308 | BP9: 0.75769231 | BQ9: 0.65053763 | BR9: 0.56849315 | BS9: 0.43115942 | BT9: 0.59230769 | BU9: 0.49230769 | BV9: 0.61827957 | BW9: 0.79285714 | BX9: 0.78409091 | BY9: 0.76719577 | BZ9: 0.77248677 | CA9: 0.78531073 | CB9: 0.55882353 | CC9: 0.5390625 | CD9: 0.57377049 | CE9: 0.54098361 | CF9: 0.58479532
C10: 6 | D10: 0.67253521 | E10: 0.50373134 | F10: 0.71875 | G10: 0.66666667 | H10: 0.61666667 | I10: 0.52702703 | J10: 0.68928571 | K10: 0.45833333 | L10: 0.61742424 | M10: 0.5978836 | N10: 0.86148649 | O10: 0.63175676 | P10: 0.54452055 | Q10: 0.71959459 | R10: 0.875 | S10: 0.79545455 | T10: 0.8030303 | U10: 0.87301587 | V10: 0.53214286 | W10: 0.6780303 | X10: 0.61904762 | Y10: 0.62433862 | Z10: 0.62711864 | AA10: 0.55405405 | AB10: 0.66071429 | AC10: 0.48484848 | AD10: 0.53030303 | AE10: 0.58730159 | AF10: 0.55067568 | AG10: 0.50337838 | AH10: 0.53424658 | AI10: 0.61486486 | AJ10: 0.55357143 | AK10: 0.56439394 | AL10: 0.49621212 | AM10: 0.51851852 | AN10: 0.57432432 | AO10: 0.66785714 | AP10: 0.6780303 | AQ10: 0.64772727 | AR10: 0.76190476 | AS10: 0.52027027 | AT10: 0.53571429 | AU10: 0.51515152 | AV10: 0.52272727 | AW10: 0.59259259 | AX10: 0.53040541 | AY10: 0.76785714 | AZ10: 0.45833333 | BA10: 0.60227273 | BB10: 0.56613757 | BC10: 0.69594595 | BD10: 0.825 | BE10: 0.60606061 | BF10: 0.6780303 | BG10: 0.58201058 | BH10: 0.53767123 | BI10: 0.5942029 | BJ10: 0.48076923 | BK10: 0.55769231 | BL10: 0.46774194 | BM10: 0.72635135 | BN10: 0.85357143 | BO10: 0.61742424 | BP10: 0.78409091 | BQ10: 0.70899471 | BR10: 0.48310811 | BS10: 0.63214286 | BT10: 0.48106061 | BU10: 0.60606061 | BV10: 0.52380952 | BW10: 0.50352113 | BX10: 0.55597015 | BY10: 0.64583333 | BZ10: 0.63020833 | CA10: 0.61111111 | CB10: 0.63768116 | CC10: 0.59230769 | CD10: 0.47311828 | CE10: 0.52688172 | CF10: 0.5862069
C11: 5 | D11: 0.66319444 | E11: 0.59926471 | F11: 0.6171875 | G11: 0.4921875 | H11: 0.64480874 | I11: 0.57666667 | J11: 0.73943662 | K11: 0.5858209 | L11: 0.64552239 | M11: 0.609375 | N11: 0.73333333 | O11: 0.77666667 | P11: 0.60810811 | Q11: 0.59333333 | R11: 0.59859155 | S11: 0.74253731 | T11: 0.63059701 | U11: 0.76041667 | V11: 0.57042254 | W11: 0.70522388 | X11: 0.60416667 | Y11: 0.57291667 | Z11: 0.59444444 | AA11: 0.58333333 | AB11: 0.63028169 | AC11: 0.48134328 | AD11: 0.54850746 | AE11: 0.55729167 | AF11: 0.52666667 | AG11: 0.51 | AH11: 0.52364865 | AI11: 0.55 | AJ11: 0.60211268 | AK11: 0.54104478 | AL11: 0.56716418 | AM11: 0.55729167 | AN11: 0.74333333 | AO11: 0.8028169 | AP11: 0.73134328 | AQ11: 0.83208955 | AR11: 0.859375 | AS11: 0.52 | AT11: 0.52816901 | AU11: 0.51865672 | AV11: 0.51492537 | AW11: 0.59895833 | AX11: 0.54333333 | AY11: 0.74647887 | AZ11: 0.59328358 | BA11: 0.61940299 | BB11: 0.57291667 | BC11: 0.74 | BD11: 0.84507042 | BE11: 0.65298507 | BF11: 0.75746269 | BG11: 0.609375 | BH11: 0.5 | BI11: 0.69642857 | BJ11: 0.53030303 | BK11: 0.56818182 | BL11: 0.47619048 | BM11: 0.67 | BN11: 0.6443662 | BO11: 0.71268657 | BP11: 0.71641791 | BQ11: 0.65104167 | BR11: 0.56666667 | BS11: 0.66901408 | BT11: 0.57835821 | BU11: 0.64552239 | BV11: 0.59375 | BW11: 0.82746479 | BX11: 0.90298507 | BY11: 0.53571429 | BZ11: 0.8531746 | CA11: 0.84444444 | CB11: 0.66785714 | CC11: 0.59090909 | CD11: 0.44444444 | CE11: 0.49206349 | CF11: 0.59887006
C12: 4 | D12: 0.59246575 | E12: 0.61956522 | F12: 0.55384615 | G12: 0.53076923 | H12: 0.6344086 | I12: 0.58552632 | J12: 0.66666667 | K12: 0.59191176 | L12: 0.66544118 | M12: 0.58984375 | N12: 0.64473684 | O12: 0.78947368 | P12: 0.59666667 | Q12: 0.50493421 | R12: 0.68055556 | S12: 0.66176471 | T12: 0.51838235 | U12: 0.57421875 | V12: 0.60069444 | W12: 0.59558824 | X12: 0.609375 | Y12: 0.625 | Z12: 0.56284153 | AA12: 0.57894737 | AB12: 0.5625 | AC12: 0.52573529 | AD12: 0.58455882 | AE12: 0.5 | AF12: 0.49671053 | AG12: 0.61184211 | AH12: 0.51333333 | AI12: 0.59210526 | AJ12: 0.58680556 | AK12: 0.52205882 | AL12: 0.55882353 | AM12: 0.52734375 | AN12: 0.74671053 | AO12: 0.73958333 | AP12: 0.74632353 | AQ12: 0.79779412 | AR12: 0.78125 | AS12: 0.47368421 | AT12: 0.62847222 | AU12: 0.47058824 | AV12: 0.58455882 | AW12: 0.5546875 | AX12: 0.50986842 | AY12: 0.65277778 | AZ12: 0.5625 | BA12: 0.62867647 | BB12: 0.5390625 | BC12: 0.72697368 | BD12: 0.78125 | BE12: 0.66544118 | BF12: 0.75367647 | BG12: 0.6875 | BH12: 0.53333333 | BI12: 0.64788732 | BJ12: 0.52985075 | BK12: 0.64925373 | BL12: 0.44270833 | BM12: 0.64802632 | BN12: 0.50347222 | BO12: 0.69117647 | BP12: 0.63235294 | BQ12: 0.6640625 | BR12: 0.60197368 | BS12: 0.72569444 | BT12: 0.60661765 | BU12: 0.67279412 | BV12: 0.64453125 | BW12: 0.82746479 | BX12: 0.88059701 | BY12: 0.51984127 | BZ12: 0.81746032 | CA12: 0.82777778 | CB12: 0.70422535 | CC12: 0.65298507 | CD12: 0.49479167 | CE12: 0.546875 | CF12: 0.62777778
C14: -12 | D14: -0.011538462 | E14: 0.15053763 | F14: 0.24712644 | G14: 0.24137931 | H14: 0.17272727 | I14: 0.066176471 | J14: 0.1171875 | K14: 0.0027322404 | L14: 0.030054645 | M14: 0.043859649 | N14: 0.22426471 | O14: 0.15441176 | P14: 0.20522388 | Q14: 0.26102941 | R14: 0.08203125 | S14: 0.22131148 | T14: 0.090163934 | U14: 0.12573099 | V14: 0.0546875 | W14: 0.1010929 | X14: 0.073099415 | Y14: 0.090643275 | Z14: 0.027777778 | AA14: 0.0036764706 | AB14: 0.19921875 | AC14: -0.040983607 | AD14: 0.13387978 | AE14: 0.084795322 | AF14: 0.091911765 | AG14: 0.018382353 | AH14: -0.0037313433 | AI14: 0.15441176 | AJ14: 0.16015625 | AK14: -0.013661202 | AL14: 0.046448087 | AM14: 0.084795322 | AN14: 0.19117647 | AO14: -0.00390625 | AP14: 0.37431694 | AQ14: 0.22677596 | AR14: 0.31871345 | AS14: 0.0036764706 | AT14: 0.03515625 | AU14: 0.079234973 | AV14: 0.035519126 | AW14: 0.038011696 | AX14: 0.044117647 | AY14: 0.20703125 | AZ14: -0.024590164 | BA14: 0.090163934 | BB14: 0.0087719298 | BC14: 0.069852941 | BD14: 0.16015625 | BE14: -0.030054645 | BF14: 0.1010929 | BG14: 0.055555556 | BH14: -0.041044776 | BI14: 0.26041667 | BJ14: 0.23888889 | BK14: 0.25 | BL14: 0.27380952 | BM14: 0.066176471 | BN14: 0.2109375 | BO14: 0.057377049 | BP14: 0.16120219 | BQ14: 0.11403509 | BR14: 0.029411765 | BS14: 0.05078125 | BT14: 0.11748634 | BU14: 0.057377049 | BV14: 0.073099415 | BW14: 0.23461538 | BX14: 0.15591398 | BY14: 0.028735632 | BZ14: 0.13218391 | CA14: 0.16363636 | CB14: 0.11458333 | CC14: 0.32222222 | CD14: 0.125 | CE14: 0.33928571 | CF14: 0
C15: -11 | D15: 0.079545455 | E15: 0.044973545 | F15: 0.15536723 | G15: 0.031073446 | H15: -0.0089285714 | I15: 0.17028986 | J15: 0.18846154 | K15: 0.10752688 | L15: 0.15053763 | M15: 0.11494253 | N15: 0.21014493 | O15: 0.16666667 | P15: 0.20955882 | Q15: 0.26630435 | R15: 0.11923077 | S15: 0.1827957 | T15: 0.091397849 | U15: 0.1954023 | V15: 0.038461538 | W15: 0.032258065 | X15: 0.074712644 | Y15: 0.074712644 | Z15: 0 | AA15: 0.11594203 | AB15: 0.17307692 | AC15: 0.064516129 | AD15: 0.13978495 | AE15: 0.086206897 | AF15: 0.047101449 | AG15: 0.010869565 | AH15: 0.047794118 | AI15: 0.18115942 | AJ15: 0.14615385 | AK15: -0.021505376 | AL15: 0.086021505 | AM15: 0.063218391 | AN15: 0.22463768 | AO15: -0.034615385 | AP15: 0.34946237 | AQ15: 0.22580645 | AR15: 0.32758621 | AS15: 0.10869565 | AT15: 0.0076923077 | AU15: 0.14516129 | AV15: 0.11827957 | AW15: 0.13218391 | AX15: 0.16666667 | AY15: 0.21153846 | AZ15: 0.16129032 | BA15: 0.19354839 | BB15: 0.1954023 | BC15: 0.032608696 | BD15: 0.11923077 | BE15: 0.043010753 | BF15: 0.053763441 | BG15: 0.034482759 | BH15: 0.055147059 | BI15: 0.04296875 | BJ15: 0.17213115 | BK15: 0.013661202 | BL15: 0.090643275 | BM15: 0.072463768 | BN15: 0.1 | BO15: 0.048387097 | BP15: 0.12365591 | BQ15: 0.068965517 | BR15: 0.083333333 | BS15: 0.053846154 | BT15: 0.10215054 | BU15: 0.053763441 | BV15: 0.068965517 | BW15: 0.14015152 | BX15: 0.097883598 | BY15: 0.16666667 | BZ15: 0.042372881 | CA15: 0.080357143 | CB15: -0.01171875 | CC15: 0.2431694 | CD15: 0.28947368 | CE15: 0.42982456 | CF15: 0.16666667
C16: -10 | D16: 0.12313433 | E16: 0.20833333 | F16: 0.0055555556 | G16: 0.17222222 | H16: 0.023809524 | I16: 0.31428571 | J16: 0.26515152 | K16: 0.22486772 | L16: 0.2989418 | M16: 0.24576271 | N16: 0.092857143 | O16: 0.20714286 | P16: 0.18478261 | Q16: 0.28928571 | R16: -0.011363636 | S16: 0.082010582 | T16: 0.071428571 | U16: 0.14971751 | V16: 0.049242424 | W16: -0.029100529 | X16: 0.064971751 | Y16: 0.070621469 | Z16: 0 | AA16: 0.039285714 | AB16: 0.068181818 | AC16: 0.060846561 | AD16: 0.076719577 | AE16: 0.048022599 | AF16: -0.021428571 | AG16: 0.0035714286 | AH16: 0.10507246 | AI16: 0.15357143 | AJ16: 0.068181818 | AK16: 0.03968254 | AL16: 0.023809524 | AM16: 0.0028248588 | AN16: 0.2 | AO16: 0.022727273 | AP16: 0.1031746 | AQ16: 0.05026455 | AR16: 0.21186441 | AS16: 0.15714286 | AT16: 0.071969697 | AU16: 0.2037037 | AV16: 0.15608466 | AW16: 0.22316384 | AX16: 0.28214286 | AY16: 0.17424242 | AZ16: 0.21957672 | BA16: 0.23015873 | BB16: 0.1779661 | BC16: 0.0035714286 | BD16: 0.03030303 | BE16: 0.013227513 | BF16: 0.029100529 | BG16: 0.025423729 | BH16: 0.2173913 | BI16: 0.1 | BJ16: 0.048387097 | BK16: 0.17204301 | BL16: 0.057471264 | BM16: 0.10714286 | BN16: 0.053030303 | BO16: 0.097883598 | BP16: 0.1031746 | BQ16: 0.048022599 | BR16: 0.15 | BS16: 0.041666667 | BT16: 0.12962963 | BU16: 0.14021164 | BV16: 0.13841808 | BW16: 0.14925373 | BX16: 0.0625 | BY16: 0.083333333 | BZ16: 0.061111111 | CA16: -0.035714286 | CB16: 0.034615385 | CC16: 0.069892473 | CD16: 0.3045977 | CE16: 0.1954023 | CF16: 0.2
C17: -9 | D17: 0.20955882 | E17: 0.3359375 | F17: 0.095628415 | G17: 0.31967213 | H17: 0.16666667 | I17: 0.21478873 | J17: 0.1119403 | K17: 0.19791667 | L17: 0.171875 | M17: 0.17222222 | N17: 0.095070423 | O17: 0.031690141 | P17: 0.025 | Q17: 0.084507042 | R17: 0.19776119 | S17: 0.11979167 | T17: 0.21354167 | U17: 0.094444444 | V17: 0.089552239 | W17: -0.057291667 | X17: 0.083333333 | Y17: 0.072222222 | Z17: 0.095238095 | AA17: -0.049295775 | AB17: -0.041044776 | AC17: 0.015625 | AD17: -0.020833333 | AE17: -0.038888889 | AF17: -0.059859155 | AG17: 0.0035211268 | AH17: 0.1 | AI17: 0.16197183 | AJ17: 0.12313433 | AK17: 0.036458333 | AL17: 0.10416667 | AM17: 0.016666667 | AN17: 0.19366197 | AO17: 0.03358209 | AP17: 0.03125 | AQ17: 0.098958333 | AR17: 0.038888889 | AS17: 0.088028169 | AT17: 0.01119403 | AU17: 0.13020833 | AV17: 0.052083333 | AW17: 0.15555556 | AX17: 0.1443662 | AY17: 0.059701493 | AZ17: 0.13541667 | BA17: 0.098958333 | BB17: 0.088888889 | BC17: 0.063380282 | BD17: -0.03358209 | BE17: 0.026041667 | BF17: 0.026041667 | BG17: -0.0055555556 | BH17: 0.225 | BI17: 0.17045455 | BJ17: 0.087301587 | BK17: 0.27777778 | BL17: 0.13276836 | BM17: 0.045774648 | BN17: 0.14552239 | BO17: 0.010416667 | BP17: -0.020833333 | BQ17: -0.044444444 | BR17: 0.1971831 | BS17: 0.070895522 | BT17: 0.14583333 | BU17: 0.13020833 | BV17: 0.16666667 | BW17: 0.32720588 | BX17: 0.3359375 | BY17: 0.21584699 | BZ17: 0.3852459 | CA17: 0.30701754 | CB17: 0.041666667 | CC17: 0.03968254 | CD17: 0.31355932 | CE17: 0.11016949 | CF17: 0.16071429
C18: -8 | D18: 0.21014493 | E18: 0.32692308 | F18: 0.1827957 | G18: 0.32258065 | H18: 0.1954023 | I18: 0.038194444 | J18: -0.080882353 | K18: 0.078125 | L18: -0.06640625 | M18: 0.030054645 | N18: 0.23958333 | O18: 0.0069444444 | P18: 0.042253521 | Q18: 0.090277778 | R18: 0.27941176 | S18: 0.19335938 | T18: 0.2578125 | U18: 0.23770492 | V18: 0.084558824 | W18: 0.12890625 | X18: 0.11202186 | Y18: 0.11202186 | Z18: 0.10818713 | AA18: -0.069444444 | AB18: -0.080882353 | AC18: 0.015625 | AD18: -0.06640625 | AE18: -0.1010929 | AF18: 0.14236111 | AG18: 0.010416667 | AH18: 0.11267606 | AI18: 0.16666667 | AJ18: 0.040441176 | AK18: 0.16796875 | AL18: 0.12109375 | AM18: -0.035519126 | AN18: 0.065972222 | AO18: 0.16176471 | AP18: 0.03125 | AQ18: 0.14453125 | AR18: 0.21584699 | AS18: 0.16319444 | AT18: 0.073529412 | AU18: 0.09375 | AV18: 0.08203125 | AW18: 0.13934426 | AX18: 0 | AY18: -0.044117647 | AZ18: 0.09765625 | BA18: -0.01953125 | BB18: 0.035519126 | BC18: -0.0069444444 | BD18: 0.073529412 | BE18: -0.01171875 | BF18: 0.06640625 | BG18: -0.019125683 | BH18: 0.12323944 | BI18: 0.12313433 | BJ18: 0.015625 | BK18: 0.13020833 | BL18: 0 | BM18: 0.13194444 | BN18: 0.16911765 | BO18: -0.0546875 | BP18: 0.15625 | BQ18: 0.079234973 | BR18: 0.1875 | BS18: 0.11029412 | BT18: 0.16796875 | BU18: 0.12890625 | BV18: 0.16666667 | BW18: 0.2826087 | BX18: 0.33076923 | BY18: 0.18817204 | BZ18: 0.30107527 | CA18: 0.29885057 | CB18: 0.026119403 | CC18: 0.109375 | CD18: 0.15 | CE18: -0.016666667 | CF18: 0.14285714
C19: -7 | D19: 0.18571429 | E19: 0.098484848 | F19: 0.18253968 | G19: 0.25132275 | H19: 0.13841808 | I19: 0.020547945 | J19: 0.17391304 | K19: -0.023076923 | L19: 0.12692308 | M19: 0.080645161 | N19: 0.35958904 | O19: 0.1369863 | P19: 0.11111111 | Q19: 0.26712329 | R19: 0.37318841 | S19: 0.26153846 | T19: 0.4 | U19: 0.41397849 | V19: -0.010869565 | W19: 0.16923077 | X19: 0.12365591 | Y19: 0.10752688 | Z19: 0.13793103 | AA19: 0.061643836 | AB19: 0.09057971 | AC19: 0 | AD19: -0.034615385 | AE19: -0.091397849 | AF19: 0.1130137 | AG19: 0.023972603 | AH19: 0.086805556 | AI19: 0.12671233 | AJ19: 0.10144928 | AK19: 0.088461538 | AL19: 0.023076923 | AM19: 0.032258065 | AN19: 0.13356164 | AO19: 0.23188406 | AP19: 0.22307692 | AQ19: 0.22307692 | AR19: 0.33333333 | AS19: 0.15410959 | AT19: 0.02173913 | AU19: 0.061538462 | AV19: 0.057692308 | AW19: 0.064516129 | AX19: -0.044520548 | AY19: 0.14855072 | AZ19: 0.015384615 | BA19: 0.10769231 | BB19: 0.037634409 | BC19: 0.15068493 | BD19: 0.19927536 | BE19: -0.046153846 | BF19: 0.12692308 | BG19: 0.064516129 | BH19: 0.055555556 | BI19: 0.025735294 | BJ19: 0.08203125 | BK19: 0.01953125 | BL19: 0.035519126 | BM19: 0.19178082 | BN19: 0.32608696 | BO19: 0.076923077 | BP19: 0.25769231 | BQ19: 0.15053763 | BR19: 0.068493151 | BS19: -0.06884058 | BT19: 0.092307692 | BU19: -0.0076923077 | BV19: 0.11827957 | BW19: 0.29285714 | BX19: 0.28409091 | BY19: 0.26719577 | BZ19: 0.27248677 | CA19: 0.28531073 | CB19: 0.058823529 | CC19: 0.0390625 | CD19: 0.073770492 | CE19: 0.040983607 | CF19: 0.084795322
C20: -6 | D20: 0.17253521 | E20: 0.0037313433 | F20: 0.21875 | G20: 0.16666667 | H20: 0.11666667 | I20: 0.027027027 | J20: 0.18928571 | K20: -0.041666667 | L20: 0.11742424 | M20: 0.097883598 | N20: 0.36148649 | O20: 0.13175676 | P20: 0.044520548 | Q20: 0.21959459 | R20: 0.375 | S20: 0.29545455 | T20: 0.3030303 | U20: 0.37301587 | V20: 0.032142857 | W20: 0.1780303 | X20: 0.11904762 | Y20: 0.12433862 | Z20: 0.12711864 | AA20: 0.054054054 | AB20: 0.16071429 | AC20: -0.015151515 | AD20: 0.03030303 | AE20: 0.087301587 | AF20: 0.050675676 | AG20: 0.0033783784 | AH20: 0.034246575 | AI20: 0.11486486 | AJ20: 0.053571429 | AK20: 0.064393939 | AL20: -0.0037878788 | AM20: 0.018518519 | AN20: 0.074324324 | AO20: 0.16785714 | AP20: 0.1780303 | AQ20: 0.14772727 | AR20: 0.26190476 | AS20: 0.02027027 | AT20: 0.035714286 | AU20: 0.015151515 | AV20: 0.022727273 | AW20: 0.092592593 | AX20: 0.030405405 | AY20: 0.26785714 | AZ20: -0.041666667 | BA20: 0.10227273 | BB20: 0.066137566 | BC20: 0.19594595 | BD20: 0.325 | BE20: 0.10606061 | BF20: 0.1780303 | BG20: 0.082010582 | BH20: 0.037671233 | BI20: 0.094202899 | BJ20: -0.019230769 | BK20: 0.057692308 | BL20: -0.032258065 | BM20: 0.22635135 | BN20: 0.35357143 | BO20: 0.11742424 | BP20: 0.28409091 | BQ20: 0.20899471 | BR20: -0.016891892 | BS20: 0.13214286 | BT20: -0.018939394 | BU20: 0.10606061 | BV20: 0.023809524 | BW20: 0.0035211268 | BX20: 0.055970149 | BY20: 0.14583333 | BZ20: 0.13020833 | CA20: 0.11111111 | CB20: 0.13768116 | CC20: 0.092307692 | CD20: -0.02688172 | CE20: 0.02688172 | CF20: 0.086206897
C21: -5 | D21: 0.16319444 | E21: 0.099264706 | F21: 0.1171875 | G21: -0.0078125 | H21: 0.14480874 | I21: 0.076666667 | J21: 0.23943662 | K21: 0.085820896 | L21: 0.14552239 | M21: 0.109375 | N21: 0.23333333 | O21: 0.27666667 | P21: 0.10810811 | Q21: 0.093333333 | R21: 0.098591549 | S21: 0.24253731 | T21: 0.13059701 | U21: 0.26041667 | V21: 0.070422535 | W21: 0.20522388 | X21: 0.10416667 | Y21: 0.072916667 | Z21: 0.094444444 | AA21: 0.083333333 | AB21: 0.13028169 | AC21: -0.018656716 | AD21: 0.048507463 | AE21: 0.057291667 | AF21: 0.026666667 | AG21: 0.01 | AH21: 0.023648649 | AI21: 0.05 | AJ21: 0.10211268 | AK21: 0.041044776 | AL21: 0.067164179 | AM21: 0.057291667 | AN21: 0.24333333 | AO21: 0.3028169 | AP21: 0.23134328 | AQ21: 0.33208955 | AR21: 0.359375 | AS21: 0.02 | AT21: 0.028169014 | AU21: 0.018656716 | AV21: 0.014925373 | AW21: 0.098958333 | AX21: 0.043333333 | AY21: 0.24647887 | AZ21: 0.093283582 | BA21: 0.11940299 | BB21: 0.072916667 | BC21: 0.24 | BD21: 0.34507042 | BE21: 0.15298507 | BF21: 0.25746269 | BG21: 0.109375 | BH21: 0 | BI21: 0.19642857 | BJ21: 0.03030303 | BK21: 0.068181818 | BL21: -0.023809524 | BM21: 0.17 | BN21: 0.1443662 | BO21: 0.21268657 | BP21: 0.21641791 | BQ21: 0.15104167 | BR21: 0.066666667 | BS21: 0.16901408 | BT21: 0.078358209 | BU21: 0.14552239 | BV21: 0.09375 | BW21: 0.32746479 | BX21: 0.40298507 | BY21: 0.035714286 | BZ21: 0.3531746 | CA21: 0.34444444 | CB21: 0.16785714 | CC21: 0.090909091 | CD21: -0.055555556 | CE21: -0.0079365079 | CF21: 0.098870056
C22: -4 | D22: 0.092465753 | E22: 0.11956522 | F22: 0.053846154 | G22: 0.030769231 | H22: 0.1344086 | I22: 0.085526316 | J22: 0.16666667 | K22: 0.091911765 | L22: 0.16544118 | M22: 0.08984375 | N22: 0.14473684 | O22: 0.28947368 | P22: 0.096666667 | Q22: 0.0049342105 | R22: 0.18055556 | S22: 0.16176471 | T22: 0.018382353 | U22: 0.07421875 | V22: 0.10069444 | W22: 0.095588235 | X22: 0.109375 | Y22: 0.125 | Z22: 0.06284153 | AA22: 0.078947368 | AB22: 0.0625 | AC22: 0.025735294 | AD22: 0.084558824 | AE22: 0 | AF22: -0.0032894737 | AG22: 0.11184211 | AH22: 0.013333333 | AI22: 0.092105263 | AJ22: 0.086805556 | AK22: 0.022058824 | AL22: 0.058823529 | AM22: 0.02734375 | AN22: 0.24671053 | AO22: 0.23958333 | AP22: 0.24632353 | AQ22: 0.29779412 | AR22: 0.28125 | AS22: -0.026315789 | AT22: 0.12847222 | AU22: -0.029411765 | AV22: 0.084558824 | AW22: 0.0546875 | AX22: 0.0098684211 | AY22: 0.15277778 | AZ22: 0.0625 | BA22: 0.12867647 | BB22: 0.0390625 | BC22: 0.22697368 | BD22: 0.28125 | BE22: 0.16544118 | BF22: 0.25367647 | BG22: 0.1875 | BH22: 0.033333333 | BI22: 0.14788732 | BJ22: 0.029850746 | BK22: 0.14925373 | BL22: -0.057291667 | BM22: 0.14802632 | BN22: 0.0034722222 | BO22: 0.19117647 | BP22: 0.13235294 | BQ22: 0.1640625 | BR22: 0.10197368 | BS22: 0.22569444 | BT22: 0.10661765 | BU22: 0.17279412 | BV22: 0.14453125 | BW22: 0.32746479 | BX22: 0.38059701 | BY22: 0.01984127 | BZ22: 0.31746032 | CA22: 0.32777778 | CB22: 0.20422535 | CC22: 0.15298507 | CD22: -0.0052083333 | CE22: 0.046875 | CF22: 0.12777778
C24: Max AUROC in indicator | D24: 0.21014493 | E24: 0.3359375 | F24: 0.24712644 | G24: 0.32258065 | H24: 0.1954023 | I24: 0.31428571 | J24: 0.26515152 | K24: 0.22486772 | L24: 0.2989418 | M24: 0.24576271 | N24: 0.36148649 | O24: 0.28947368 | P24: 0.20955882 | Q24: 0.28928571 | R24: 0.375 | S24: 0.29545455 | T24: 0.4 | U24: 0.41397849 | V24: 0.10069444 | W24: 0.20522388 | X24: 0.12365591 | Y24: 0.125 | Z24: 0.13793103 | AA24: 0.11594203 | AB24: 0.19921875 | AC24: 0.064516129 | AD24: 0.13978495 | AE24: 0.087301587 | AF24: 0.14236111 | AG24: 0.11184211 | AH24: 0.11267606 | AI24: 0.18115942 | AJ24: 0.16015625 | AK24: 0.16796875 | AL24: 0.12109375 | AM24: 0.084795322 | AN24: 0.24671053 | AO24: 0.3028169 | AP24: 0.37431694 | AQ24: 0.33208955 | AR24: 0.359375 | AS24: 0.16319444 | AT24: 0.12847222 | AU24: 0.2037037 | AV24: 0.15608466 | AW24: 0.22316384 | AX24: 0.28214286 | AY24: 0.26785714 | AZ24: 0.21957672 | BA24: 0.23015873 | BB24: 0.1954023 | BC24: 0.24 | BD24: 0.34507042 | BE24: 0.16544118 | BF24: 0.25746269 | BG24: 0.1875 | BH24: 0.225 | BI24: 0.26041667 | BJ24: 0.23888889 | BK24: 0.27777778 | BL24: 0.27380952 | BM24: 0.22635135 | BN24: 0.35357143 | BO24: 0.21268657 | BP24: 0.28409091 | BQ24: 0.20899471 | BR24: 0.1971831 | BS24: 0.22569444 | BT24: 0.16796875 | BU24: 0.17279412 | BV24: 0.16666667 | BW24: 0.32746479 | BX24: 0.40298507 | BY24: 0.26719577 | BZ24: 0.3852459 | CA24: 0.34444444 | CB24: 0.20422535 | CC24: 0.32222222 | CD24: 0.31355932 | CE24: 0.42982456 | CF24: 0.2
C25: Sum of max AUROC in Mj | D25: 1.3111918 | I25: 1.3490095 | N25: 0.86051899 | Q25: 1.7737188 | V25: 0.69250527 | AA25: 0.60676344 | AF25: 0.36687927 | AI25: 0.71517349 | AN25: 1.6153089 | AS25: 0.87461887 | AX25: 1.1951377 | BC25: 1.1954743 | BH25: 1.2758929 | BM25: 1.285695 | BR25: 0.93030708 | BW25: 1.727336 | CB25: 1.4698315
C26: Number of indicators in Mj | D26: 5 | I26: 5 | N26: 3 | Q26: 5 | V26: 5 | AA26: 5 | AF26: 3 | AI26: 5 | AN26: 5 | AS26: 5 | AX26: 5 | BC26: 5 | BH26: 5 | BM26: 5 | BR26: 5 | BW26: 5 | CB26: 5
C27: Average sum of max AUROC in Mj | D27: 0.26223836 | I27: 0.26980189 | N27: 0.28683966 | Q27: 0.35474375 | V27: 0.13850105 | AA27: 0.12135269 | AF27: 0.12229309 | AI27: 0.1430347 | AN27: 0.32306178 | AS27: 0.17492377 | AX27: 0.23902755 | BC27: 0.23909486 | BH27: 0.25517857 | BM27: 0.25713899 | BR27: 0.18606142 | BW27: 0.3454672 | CB27: 0.29396629
C28: Sum of average max in sector | D28: 1.1736237 | I28: 1.1736237 | N28: 1.1736237 | Q28: 1.1736237 | V28: 0.38214683 | AA28: 0.38214683 | AF28: 0.38214683 | AI28: 0.64102026 | AN28: 0.64102026 | AS28: 0.64102026 | AX28: 0.73330098 | BC28: 0.73330098 | BH28: 0.73330098 | BM28: 0.44320041 | BR28: 0.44320041 | BW28: 0.63943349 | CB28: 0.63943349
C29: Weight indicator in Mj | D29: 0.16027017 | E29: 0.25620775 | F29: 0.18847466 | G29: 0.24602094 | H29: 0.14902648 | I29: 0.23297517 | J29: 0.19655275 | K29: 0.16669099 | L29: 0.22160096 | M29: 0.18218012 | N29: 0.42007961 | O29: 0.3363943 | P29: 0.24352609 | Q29: 0.16309559 | R29: 0.21142021 | S29: 0.1665735 | T29: 0.2255149 | U29: 0.23339579 | V29: 0.14540603 | W29: 0.29634992 | X29: 0.17856314 | Y29: 0.18050404 | Z29: 0.19917687 | AA29: 0.19108275 | AB29: 0.32833018 | AC29: 0.10632831 | AD29: 0.230378 | AE29: 0.14388076 | AF29: 0.38803258 | AG29: 0.30484716 | AH29: 0.30712026 | AI29: 0.25330835 | AJ29: 0.22394042 | AK29: 0.23486434 | AL29: 0.1693208 | AM29: 0.11856609 | AN29: 0.15273272 | AO29: 0.18746687 | AP29: 0.23173087 | AQ29: 0.20558888 | AR29: 0.22248066 | AS29: 0.18658921 | AT29: 0.14688938 | AU29: 0.23290568 | AV29: 0.1784602 | AW29: 0.25515553 | AX29: 0.2360756 | AY29: 0.2241224 | AZ29: 0.18372503 | BA29: 0.19257925 | BB29: 0.16349772 | BC29: 0.20075714 | BD29: 0.2886473 | BE29: 0.13838957 | BF29: 0.21536447 | BG29: 0.15684152 | BH29: 0.1763471 | BI29: 0.20410544 | BJ29: 0.18723272 | BK29: 0.21771246 | BL29: 0.21460229 | BM29: 0.1760537 | BN29: 0.27500413 | BO29: 0.16542537 | BP29: 0.22096292 | BQ29: 0.16255388 | BR29: 0.21195485 | BS29: 0.24260209 | BT29: 0.18055194 | BU29: 0.1857388 | BV29: 0.17915232 | BW29: 0.18957794 | BX29: 0.23329861 | BY29: 0.15468662 | BZ29: 0.22302893 | CA29: 0.1994079 | CB29: 0.13894474 | CC29: 0.21922393 | CD29: 0.21333012 | CE29: 0.29243119 | CF29: 0.13607002
C30: Weight Mj in Sector | D30: 0.22344331 | E30: 0.22344331 | F30: 0.22344331 | G30: 0.22344331 | H30: 0.22344331 | I30: 0.22988791 | J30: 0.22988791 | K30: 0.22988791 | L30: 0.22988791 | M30: 0.22988791 | N30: 0.24440515 | O30: 0.24440515 | P30: 0.24440515 | Q30: 0.30226363 | R30: 0.30226363 | S30: 0.30226363 | T30: 0.30226363 | U30: 0.30226363 | V30: 0.36242889 | W30: 0.36242889 | X30: 0.36242889 | Y30: 0.36242889 | Z30: 0.36242889 | AA30: 0.31755513 | AB30: 0.31755513 | AC30: 0.31755513 | AD30: 0.31755513 | AE30: 0.31755513 | AF30: 0.32001597 | AG30: 0.32001597 | AH30: 0.32001597 | AI30: 0.223136 | AJ30: 0.223136 | AK30: 0.223136 | AL30: 0.223136 | AM30: 0.223136 | AN30: 0.50398062 | AO30: 0.50398062 | AP30: 0.50398062 | AQ30: 0.50398062 | AR30: 0.50398062 | AS30: 0.27288338 | AT30: 0.27288338 | AU30: 0.27288338 | AV30: 0.27288338 | AW30: 0.27288338 | AX30: 0.32596104 | AY30: 0.32596104 | AZ30: 0.32596104 | BA30: 0.32596104 | BB30: 0.32596104 | BC30: 0.32605283 | BD30: 0.32605283 | BE30: 0.32605283 | BF30: 0.32605283 | BG30: 0.32605283 | BH30: 0.34798613 | BI30: 0.34798613 | BJ30: 0.34798613 | BK30: 0.34798613 | BL30: 0.34798613 | BM30: 0.58018672 | BN30: 0.58018672 | BO30: 0.58018672 | BP30: 0.58018672 | BQ30: 0.58018672 | BR30: 0.41981328 | BS30: 0.41981328 | BT30: 0.41981328 | BU30: 0.41981328 | BV30: 0.41981328 | BW30: 0.54027073 | BX30: 0.54027073 | BY30: 0.54027073 | BZ30: 0.54027073 | CA30: 0.54027073 | CB30: 0.45972927 | CC30: 0.45972927 | CD30: 0.45972927 | CE30: 0.45972927 | CF30: 0.45972927
C31: Weight indicator in Sector | D31: 0.035811297 | E31: 0.057247908 | F31: 0.042113404 | G31: 0.054971735 | H31: 0.03329897 | I31: 0.053558176 | J31: 0.0451851 | K31: 0.038320244 | L31: 0.050943383 | M31: 0.041881008 | N31: 0.10266962 | O31: 0.082216498 | P31: 0.059519029 | Q31: 0.049297866 | R31: 0.063904642 | S31: 0.050349112 | T31: 0.068164951 | U31: 0.07054706 | V31: 0.052699348 | W31: 0.10740577 | X31: 0.06471644 | Y31: 0.06541988 | Z31: 0.072187454 | AA31: 0.060679309 | AB31: 0.10426293 | AC31: 0.033765099 | AD31: 0.073157715 | AE31: 0.045690075 | AF31: 0.12417662 | AG31: 0.097555961 | AH31: 0.098283388 | AI31: 0.056522214 | AJ31: 0.04996917 | AK31: 0.05240669 | AL31: 0.037781567 | AM31: 0.026456363 | AN31: 0.076974331 | AO31: 0.094479667 | AP31: 0.11678787 | AQ31: 0.10361281 | AR31: 0.11212594 | AS31: 0.050917094 | AT31: 0.04008367 | AU31: 0.063556089 | AV31: 0.048698822 | AW31: 0.069627704 | AX31: 0.076951447 | AY31: 0.073055171 | AZ31: 0.059887202 | BA31: 0.062773332 | BB31: 0.053293887 | BC31: 0.065457433 | BD31: 0.094114268 | BE31: 0.045122312 | BF31: 0.070220194 | BG31: 0.05113862 | BH31: 0.061366344 | BI31: 0.071025861 | BJ31: 0.06515439 | BK31: 0.075760918 | BL31: 0.07467862 | BM31: 0.10214402 | BN31: 0.15955375 | BO31: 0.095977604 | BP31: 0.12819975 | BQ31: 0.094311605 | BR31: 0.088981461 | BS31: 0.10184758 | BT31: 0.075798103 | BU31: 0.077975613 | BV31: 0.07521052 | BW31: 0.10242341 | BX31: 0.12604441 | BY31: 0.083572654 | BZ31: 0.120496 | CA31: 0.10773425 | CB31: 0.063876965 | CC31: 0.10078366 | CD31: 0.098074101 | CE31: 0.13443918 | CF31: 0.062555373
CG35: =BM35+AX35+AI35+V35+D35+BW35

Sheet Indicators Data
B1: Binary | C1: Corporate | U1: Households | AH1: Government | AW1: Banking | BL1: External | BV1: Недвижимость
B2: Бинарная переменная стрессов | C2: Debt service ratio, % | H2: All Debt to GDP ratio, % | M2: Прирост реального кредита банков ЮЛ (дефлятор ВВП 2018=1) | P2: Складские запасы в промышленности к среднемесячному ОПП, % | U2: Debt_service ratio | Z2: Кредит ФЛ к ВВП | AE2: Прирост реального кредита банков ФЛ (ИПЦ 2018=1) | AH2: Обслуживание внешнего долга органов государственного управления к ВВП, % | AM2: Отношение сальдо консолидированного бюджета к ВВП, % | AR2: Долг сектора государственного управления к ВВП, % (внешний + внутренний) | AW2: Требования банков к экономике к ВВП, % | BB2: Требования банков к депозитам, % | BG2: Леверидж (активы к собственному капиталу), раз | BL2: Счет текущих операций за год, в % к ВВП | BQ2: Валовый внешний долг к ВВП | BV2: Логарифм цен на коммерческую недвижимость, скорректированных на ИПЦ, *100 | CA2: Логарифм цен на жилую недвижимость, скорректированных на ИПЦ
B3: annual SD | C3: 4.6519717 | D3: 4.5874562 | E3: 3.344885 | F3: 4.0662463 | G3: 4.7976559 | H3: 12.289269 | I3: 9.4683274 | J3: 7.1708064 | K3: 8.804995 | L3: 10.966004 | M3: 25.315729 | N3: 21.741362 | O3: 21.298855 | P3: 19.257253 | Q3: 26.908695 | R3: 15.188733 | S3: 21.530215 | T3: 22.187541 | U3: 1.9671837 | V3: 1.4948964 | W3: 1.2372818 | X3: 1.4801426 | Y3: 1.843982 | Z3: 2.9701119 | AA3: 2.7624205 | AB3: 2.1645514 | AC3: 2.6306483 | AD3: 3.2053462 | AE3: 29.186373 | AF3: 22.950311 | AG3: 20.321762 | AH3: 2.9159313 | AI3: 2.3942872 | AJ3: 1.5222995 | AK3: 2.0151551 | AL3: 2.2639326 | AM3: 3.2751737 | AN3: 4.1668575 | AO3: 2.5313914 | AP3: 3.3494982 | AQ3: 3.545354 | AR3: 16.240044 | AS3: 9.9047783 | AT3: 7.5546253 | AU3: 9.3791123 | AV3: 11.553597 | AW3: 8.9834262 | AX3: 10.291725 | AY3: 7.8287166 | AZ3: 9.6046932 | BA3: 11.680181 | BB3: 55.394634 | BC3: 39.448113 | BD3: 28.801685 | BE3: 35.909605 | BF3: 42.783588 | BG3: 1.68852 | BH3: 1.699438 | BI3: 1.0185932 | BJ3: 1.3705545 | BK3: 1.4188324 | BL3: 10.06924 | BM3: 8.350912 | BN3: 4.8284243 | BO3: 6.6101871 | BP3: 7.1536312 | BQ3: 23.416131 | BR3: 15.843223 | BS3: 12.375885 | BT3: 15.076645 | BU3: 18.896752 | BV3: 34.453306 | BW3: 32.336979 | BX3: 17.107065 | BY3: 25.815382 | BZ3: 27.248781 | CA3: 26.111375 | CB3: 21.666264 | CC3: 16.260936 | CD3: 19.668319 | CE3: 22.575179
C4: dsr | D4: dsr1 | E4: dsr2 | F4: dsr_av2 | G4: dsr_av3 | H4: ggr | I4: ggr1 | J4: ggr2 | K4: ggr_av2 | L4: ggr_av3 | M4: rcgr1 | N4: rcgr2 | O4: rcgr3 | P4: invr | Q4: invr1 | R4: invr2 | S4: invr_av2 | T4: invr_av3 | U4: d_srv | V4: d_srv1 | W4: d_srv2 | X4: d_srv_av2 | Y4: d_srv_av3 | Z4: l_gdp | AA4: l_gdp1 | AB4: l_gdp2 | AC4: l_gdp_av2 | AD4: l_gdp_av3 | AE4: rcgr1 | AF4: rcgr2 | AG4: rcgr3 | AH4: exd_s | AI4: exd_s1 | AJ4: exd_s2 | AK4: exd_s_av2 | AL4: exd_s_av3 | AM4: bb_gdp | AN4: bb_gdp1 | AO4: bb_gdp2 | AP4: bb_gdp_av2 | AQ4: bb_gdp_av3 | AR4: ggd | AS4: ggd1 | AT4: ggd2 | AU4: ggd_av2 | AV4: ggd_av3 | AW4: crr | AX4: crr1 | AY4: crr2 | AZ4: crr_av2 | BA4: crr_av3 | BB4: d_as | BC4: d_as1 | BD4: d_as2 | BE4: d_as_av2 | BF4: d_as_av3 | BG4: lvr | BH4: lvr1 | BI4: lvr2 | BJ4: lvr_av2 | BK4: lvr_av3 | BL4: ca | BM4: ca1 | BN4: ca1 | BO4: ca_av2 | BP4: ca_av3 | BQ4: gd_gdp | BR4: gd_gdp1 | BS4: gd_gdp2 | BT4: gd_gdp_av2 | BU4: gd_gdp_av3 | BV4: cest | BW4: cest1 | BX4: cest2 | BY4: cest_av2 | BZ4: cest_av3 | CA4: pest | CB4: pest1 | CC4: pest2 | CD4: pest_av2 | CE4: pest_av3
A5: Date | B5: bnr | C5: dsr | D5: dsr1 | E5: dsr2 | F5: dsr_av2 | G5: dsr_av3 | H5: ggr | I5: ggr1 | J5: ggr2 | K5: ggr_av2 | L5: ggr_av3 | M5: rcgr_c1 | N5: rcgr_c2 | O5: rcgr_c3 | P5: invr | Q5: invr1 | R5: invr2 | S5: invr_av2 | T5: invr_av3 | U5: d_srv | V5: d_srv1 | W5: d_srv2 | X5: d_srv_av2 | Y5: d_srv_av3 | Z5: l_gdp | AA5: l_gdp1 | AB5: l_gdp2 | AC5: l_gdp_av2 | AD5: l_gdp_av3 | AE5: rcgr_h1 | AF5: rcgr_h2 | AG5: rcgr_h3 | AH5: exd_s | AI5: exd_s1 | AJ5: exd_s2 | AK5: exd_s_av2 | AL5: exd_s_av3 | AM5: bb_gdp | AN5: bb_gdp1 | AO5: bb_gdp2 | AP5: bb_gdp_av2 | AQ5: bb_gdp_av3 | AR5: ggd | AS5: ggd1 | AT5: ggd2 | AU5: ggd_av2 | AV5: ggd_av3 | AW5: crr | AX5: crr1 | AY5: crr2 | AZ5: crr_av2 | BA5: crr_av3 | BB5: d_as | BC5: d_as1 | BD5: d_as2 | BE5: d_as_av2 | BF5: d_as_av3 | BG5: lvr | BH5: lvr1 | BI5: lvr2 | BJ5: lvr_av2 | BK5: lvr_av3 | BL5: ca | BM5: ca1 | BN5: ca2 | BO5: ca_av2 | BP5: ca_av3 | BQ5: gd_gdp | BR5: gd_gdp1 | BS5: gd_gdp2 | BT5: gd_gdp_av2 | BU5: gd_gdp_av3 | BV5: cest | BW5: cest1 | BX5: cest2 | BY5: cest_av2 | BZ5: cest_av3 | CA5: pest | CB5: pest1 | CC5: pest2 | CD5: pest_av2 | CE5: pest_av3
A6: 38353 | B6: 0 | H6: 16.675423 | M6: 6.2907127 | N6: 8.8411801 | P6: 59.1 | Z6: 3.8187311 | AE6: 51.524277 | AF6: 52.841901 | AH6: 0.40475931 | AM6: -1.2488304 | AR6: 8.2298964 | AW6: 18.853249 | BB6: 132.67042 | BL6: 2.4342395 | BQ6: 19.209828
A7: 38443 | B7: 0 | H7: 16.382032 | M7: 1.4126309 | N7: 5.7004646 | O7: 6.7834313 | P7: 63.15 | Z7: 4.0644619 | AE7: 49.532693 | AF7: 52.456259 | AG7: 48.62299 | AH7: 0.43814534 | AM7: -1.6460877 | AR7: 7.6678247 | AW7: 18.67585 | BB7: 130.66244 | BG7: 4.9014984 | BL7: 0.83933408 | BQ7: 17.554198
A8: 38534 | B8: 0 | H8: 16.33283 | M8: 0.0072750087 | N8: 7.0487854 | O8: 9.5492335 | P8: 59.05 | Z8: 4.3668435 | AE8: 46.268116 | AF8: 51.111797 | AG8: 49.381424 | AH8: 0.41194889 | AM8: -1.3732718 | AR8: 7.3006273 | AW8: 18.72328 | BB8: 129.78912 | BG8: 5.1501882 | BL8: 0.6544386 | BQ8: 16.877142
A9: 38626 | B9: 0 | C9: 13.16004 | H9: 16.32813 | M9: 2.2997053 | N9: 6.6219865 | O9: 7.2060843 | P9: 54.05 | Z9: 4.707525 | AE9: 45.215353 | AF9: 49.60723 | AG9: 49.549393 | AH9: 0.44572862 | AM9: 0.58508832 | AR9: 7.2359532 | AW9: 18.990089 | BB9: 126.6871 | BG9: 5.1826044 | BL9: -1.5175289 | BQ9: 16.483521 | BV9: -45.134197
A10: 38718 | B10: 0 | C10: 13.245163 | H10: 16.575235 | I10: -0.10018769 | M10: 14.625582 | N10: 10.458147 | O10: 10.769314 | P10: 56.2 | Q10: -2.9 | U10: 2.286064 | Z10: 5.0414813 | AA10: 1.2227502 | AE10: 44.916934 | AF10: 48.220606 | AG10: 50.200246 | AH10: 0.44489534 | AI10: 0.040136031 | AM10: 0.80965225 | AN10: 2.0584827 | AR10: 7.8677004 | AS10: -0.36219596 | AW10: 19.907957 | AX10: 1.0547081 | BB10: 127.69285 | BC10: -4.9775734 | BG10: 5.0544193 | BL10: 0.43100222 | BM10: -2.0032373 | BQ10: 16.171109 | BR10: -3.0387192 | BV10: -32.048771
A11: 38808 | B11: 0 | C11: 12.699248 | H11: 17.216057 | I11: 0.83402451 | M11: 16.510777 | N11: 8.9617038 | O11: 9.303902 | P11: 59.05 | Q11: -4.1 | U11: 2.4397472 | Z11: 5.4044867 | AA11: 1.3400248 | AE11: 44.709732 | AF11: 47.121212 | AG11: 49.874083 | AH11: 0.40794178 | AI11: -0.030203561 | AM11: 0.79283493 | AN11: 2.4389226 | AR11: 7.4696967 | AS11: -0.19812798 | AW11: 21.05811 | AX11: 2.3822603 | BB11: 131.82011 | BC11: 1.1576676 | BG11: 5.2274262 | BH11: 0.32592783 | BL11: 1.8554286 | BM11: 1.0160946 | BQ11: 15.823752 | BR11: -1.7304458 | BV11: -21.398699 | CA11: -42.103447
A12: 38899 | B12: 0 | C12: 13.340778 | H12: 18.479285 | I12: 2.1464542 | M12: 23.074398 | N12: 11.540837 | O12: 12.390656 | P12: 55.2 | Q12: -3.85 | U12: 2.5830591 | Z12: 5.9206695 | AA12: 1.553826 | AE12: 45.555138 | AF12: 45.911627 | AG12: 49.259577 | AH12: 0.39408454 | AI12: -0.017864354 | AM12: 0.10352778 | AN12: 1.4767996 | AR12: 7.4483027 | AS12: 0.14767534 | AW12: 22.5339 | AX12: 3.8106208 | BB12: 134.6714 | BC12: 4.8822879 | BG12: 5.7016375 | BH12: 0.55144924 | BL12: 2.0937165 | BM12: 1.4392779 | BQ12: 16.488053 | BR12: -0.38908907 | BV12: 31.800243 | CA12: -40.269724
A13: 38991 | B13: 0 | C13: 13.424932 | D13: 0.26489147 | H13: 20.242207 | I13: 3.9140769 | M13: 31.683959 | N13: 16.991832 | O13: 14.975977 | P13: 55.1 | Q13: 1.05 | U13: 2.7536503 | Z13: 6.4667516 | AA13: 1.7592266 | AE13: 44.982142 | AF13: 45.098747 | AG13: 48.065534 | AH13: 0.44900435 | AI13: 0.0032757274 | AM13: -1.4321131 | AN13: -2.0172014 | AR13: 8.1688787 | AS13: 0.93292558 | AW13: 24.027624 | AX13: 5.0375358 | BB13: 137.1408 | BC13: 10.453695 | BG13: 5.7799677 | BH13: 0.5973633 | BL13: 3.7540551 | BM13: 5.271584 | BQ13: 17.598536 | BR13: 1.1150152 | BV13: 32.548217 | BW13: 77.682414 | CA13: -38.444899
A14: 39083 | B14: 0 | C14: 14.017774 | D14: 0.77261072 | H14: 21.924816 | I14: 5.3495804 | J14: 2.6246964 | K14: 4.6459158 | M14: 36.496466 | N14: 25.561024 | O14: 19.137587 | P14: 59.8 | Q14: 3.6 | R14: 0.35 | S14: 2.1875 | U14: 2.9764717 | V14: 0.69040771 | Z14: 6.8191671 | AA14: 1.7776858 | AB14: 1.500218 | AC14: 1.8452983 | AE14: 42.62421 | AF14: 43.770572 | AG14: 46.35514 | AH14: 0.39751233 | AI14: -0.047383005 | AJ14: -0.0036234868 | AK14: -0.027051189 | AM14: -2.7861548 | AN14: -3.595807 | AO14: -0.76866217 | AP14: -2.3600048 | AR14: 8.1188797 | AS14: 0.25117924 | AT14: -0.05550836 | AU14: 0.44526966 | AW14: 26.368379 | AX14: 6.4604214 | AY14: 3.7575647 | AZ14: 6.0221213 | BB14: 149.67351 | BC14: 21.980654 | BD14: 8.5015404 | BE14: 18.281725 | BG14: 5.6616065 | BH14: 0.60718722 | BL14: 5.3531317 | BM14: 4.9221295 | BN14: 1.4594461 | BO14: 4.035046 | BQ14: 19.132312 | BR14: 2.9612037 | BS14: -0.038757768 | BT14: 2.1065451 | BV14: 29.289973 | BW14: 61.338744 | CA14: -31.589411
A15: 39173 | B15: 0 | C15: 16.174563 | D15: 3.4753144 | H15: 23.041693 | I15: 5.8256357 | J15: 3.3298301 | K15: 5.1066185 | M15: 37.305241 | N15: 26.908009 | O15: 18.40955 | P15: 61.45 | Q15: 2.4 | R15: -0.85 | S15: 3.75 | U15: 3.1902437 | V15: 0.75049657 | Z15: 7.0756237 | AA15: 1.671137 | AB15: 1.5055809 | AC15: 1.7267004 | AE15: 39.926943 | AF15: 42.318337 | AG15: 44.723123 | AH15: 0.37543675 | AI15: -0.032505034 | AJ15: -0.031354297 | AK15: -0.048220903 | AM15: -2.5001316 | AN15: -3.2929665 | AO15: -0.42702195 | AP15: -1.881816 | AR15: 7.4248061 | AS15: -0.044890594 | AT15: -0.12150928 | AU15: -0.2349268 | AW15: 27.507404 | AX15: 6.449294 | AY15: 4.4157772 | AZ15: 6.2217556 | BB15: 156.55514 | BC15: 24.735031 | BD15: 12.946349 | BE15: 23.037971 | BG15: 5.8983237 | BH15: 0.67089753 | BI15: 0.49841268 | BJ15: 0.56590518 | BL15: 5.7497351 | BM15: 3.8943065 | BN15: 2.4552005 | BO15: 4.0667879 | BQ15: 21.050502 | BR15: 5.2267505 | BS15: 1.7481523 | BT15: 4.0344246 | BV15: 30.692489 | BW15: 52.091188 | CA15: -17.894371 | CB15: 24.209076
A16: 39264 | B16: 0 | C16: 18.277911 | D16: 4.9371328 | H16: 23.761352 | I16: 5.2820675 | J16: 3.7142609 | K16: 4.9938206 | M16: 34.41798 | N16: 28.746189 | O16: 19.166551 | P16: 58.65 | Q16: 3.45 | R16: -0.2 | S16: 1.1625 | U16: 3.3580052 | V16: 0.77494602 | Z16: 7.4189492 | AA16: 1.4982796 | AB16: 1.5260528 | AC16: 1.6936306 | AE16: 34.691156 | AF16: 40.123147 | AG16: 42.17147 | AH16: 0.36113063 | AI16: -0.032953905 | AJ16: -0.025409129 | AK16: -0.054688443 | AM16: -2.4531495 | AN16: -2.5566772 | AO16: -0.53993881 | AP16: -1.7280785 | AR16: 7.310368 | AS16: -0.13793465 | AT16: 0.0048703484 | AU16: -0.3189876 | AW16: 28.239442 | AX16: 5.7055413 | AY16: 4.758081 | AZ16: 5.8498488 | BB16: 158.71795 | BC16: 24.046541 | BD16: 14.464415 | BE16: 21.964193 | BG16: 6.1965551 | BH16: 0.49491757 | BI16: 0.5231834 | BJ16: 0.73953334 | BL16: 6.3120975 | BM16: 4.218381 | BN16: 2.8288294 | BO16: 4.0153501 | BQ16: 21.865528 | BR16: 5.377475 | BS16: 2.4941929 | BT16: 4.4124118 | BV16: -7.843158 | BW16: -39.643401 | CA16: -5.0858263 | CB16: 35.183898
A17: 39356 | B17: 0 | C17: 20.64782 | D17: 7.2228879 | E17: 3.7438897 | F17: 6.3552686 | H17: 25.040424 | I17: 4.7982168 | J17: 4.3561469 | K17: 5.3443269 | M17: 27.025573 | N17: 29.354766 | O17: 20.336412 | P17: 53.4 | Q17: -1.7 | R17: -0.325 | S17: -4.0375 | U17: 3.5138487 | V17: 0.76019839 | Z17: 7.7915676 | AA17: 1.324816 | AB17: 1.5420213 | AC17: 1.6847358 | AE17: 28.81339 | AF17: 36.897766 | AG17: 39.670295 | AH17: 0.50235061 | AI17: 0.053346256 | AJ17: 0.028310992 | AK17: 0.092883815 | AM17: -0.43446455 | AN17: 0.99764851 | AO17: -0.50977643 | AP17: 0.42559115 | AR17: 8.353904 | AS17: 0.18502526 | AT17: 0.55897542 | AU17: 0.7233308 | AW17: 29.266775 | AX17: 5.2391509 | AY17: 5.1383433 | AZ17: 5.6876621 | BB17: 154.17769 | BC17: 17.036892 | BD17: 13.745294 | BE17: 13.807834 | BG17: 6.288273 | BH17: 0.50830524 | BI17: 0.55283427 | BJ17: 0.70045542 | BL17: 6.6549305 | BM17: 2.9008755 | BN17: 4.0862297 | BO17: 3.6509758 | BQ17: 24.434144 | BR17: 6.8356073 | BS17: 3.9753113 | BT17: 6.3574794 | BV17: -0.48920623 | BW17: -33.037423 | BX17: 22.322495 | BY17: -2.7274682 | CA17: 4.9622551 | CB17: 43.407154
A18: 39448 | B18: 0 | C18: 22.653454 | D18: 8.63568 | E18: 4.7041454 | F18: 7.4249306 | H18: 26.290964 | I18: 4.366148 | J18: 4.8578642 | K18: 5.5058302 | L18: 6.9576734 | M18: 24.252221 | N18: 30.374344 | O18: 25.124756 | P18: 51.55 | Q18: -8.25 | R18: -2.325 | S18: -5.80625 | T18: -6.3 | U18: 3.6276274 | V18: 0.65115573 | W18: 0.67078172 | X18: 0.7399912 | Z18: 8.0105638 | AA18: 1.1913967 | AB18: 1.4845413 | AC18: 1.5182267 | AD18: 2.269209 | AE18: 25.878325 | AF18: 34.251267 | AG18: 37.80649 | AH18: 0.50125969 | AI18: 0.10374736 | AJ18: 0.028182178 | AK18: 0.084715152 | AL18: 0.081848152 | AM18: -0.72159651 | AN18: 2.0645583 | AO18: -0.76562438 | AP18: 0.26590329 | AQ18: 0.24366183 | AR18: 10.726639 | AS18: 2.607759 | AT18: 1.4294691 | AU18: 2.9563216 | AV18: 3.0102355 | AW18: 29.982404 | AX18: 3.6140252 | AY18: 5.0372233 | AZ18: 5.1187049 | BA18: 7.136399 | BB18: 150.08425 | BC18: 0.41074588 | BD18: 11.1957 | BE18: 6.2780716 | BF18: 10.896041 | BG18: 6.5190988 | BH18: 0.85749222 | BI18: 0.73233972 | BJ18: 0.79307264 | BL18: 5.8676016 | BM18: 0.51446988 | BN18: 2.7182997 | BO18: 1.8420894 | BP18: 2.9830532 | BQ18: 27.177881 | BR18: 8.045569 | BS18: 5.5033863 | BT18: 8.1073894 | BU18: 8.620496 | BV18: 6.6351422 | BW18: -22.654831 | BX18: 19.341957 | BY18: -1.1837436 | CA18: 8.7623587 | CB18: 40.35177
A19: 39539 | B19: 0 | C19: 21.476071 | D19: 5.3015082 | E19: 4.3884113 | F19: 5.0715108 | H19: 26.644374 | I19: 3.6026819 | J19: 4.7141588 | K19: 4.6447749 | L19: 6.509789 | M19: 17.567241 | N19: 27.436241 | O19: 23.79442 | P19: 51.4 | Q19: -10.05 | R19: -3.825 | S19: -5.375 | T19: -5.8208333 | U19: 3.6711736 | V19: 0.48092984 | W19: 0.61571321 | X19: 0.61584191 | Z19: 8.2901858 | AA19: 1.2145621 | AB19: 1.4428496 | AC19: 1.4267134 | AD19: 2.1995116 | AE19: 26.168854 | AF19: 33.047899 | AG19: 36.935176 | AH19: 0.49930544 | AI19: 0.1238687 | AJ19: 0.045681831 | AK19: 0.075715357 | AL19: 0.071852203 | AM19: -1.5016271 | AN19: 0.99850445 | AO19: -1.147231 | AP19: -0.32272121 | AQ19: -0.58030493 | AR19: 10.037498 | AS19: 2.6126923 | AT19: 1.2839008 | AU19: 1.9098141 | AV19: 2.1130334 | AW19: 31.64562 | AX19: 4.1382154 | AY19: 5.2937547 | AZ19: 5.5226148 | BA19: 7.8721851 | BB19: 157.92951 | BC19: 1.3743779 | BD19: 13.054704 | BE19: 11.32441 | BF19: 17.290152 | BG19: 6.8756365 | BH19: 0.97731279 | BI19: 0.82410516 | BJ19: 0.96652545 | BK19: 1.2455033 | BL19: 6.0248883 | BM19: 0.27515318 | BN19: 2.0847298 | BO19: 1.3198013 | BP19: 2.8542264 | BQ19: 26.713033 | BR19: 5.6625307 | BS19: 5.4446406 | BT19: 6.2666946 | BU19: 7.4916433 | BV19: 8.8081578 | BW19: -21.884331 | BX19: 15.103428 | BY19: -3.8462173 | CA19: 5.2491375 | CB19: 23.143508 | CC19: 23.676292 | CD19: 25.457021
A20: 39630 | B20: 0 | C20: 19.947858 | D20: 1.6699469 | E20: 3.3035398 | F20: 2.4461949 | H20: 26.448995 | I20: 2.6876425 | J20: 3.984855 | K20: 3.2708554 | L20: 5.4592141 | M20: 16.360293 | N20: 25.389136 | O20: 24.617557 | P20: 49.6 | Q20: -9.05 | R20: -2.8 | S20: -6.21875 | T20: -6.6416667 | U20: 3.665369 | V20: 0.30736388 | W20: 0.54115495 | X20: 0.45610906 | Z20: 8.6753884 | AA20: 1.2564392 | AB20: 1.3773594 | AC20: 1.4512036 | AD20: 2.2325705 | AE20: 29.541766 | AF20: 32.116461 | AG20: 36.59602 | AH20: 0.46474925 | AI20: 0.10361862 | AJ20: 0.035332358 | AK20: 0.029738709 | AL20: 0.032199338 | AM20: -2.1475353 | AN20: 0.30561413 | AO20: -1.1255316 | AP20: -0.68182168 | AQ20: -1.2382515 | AR20: 9.0830575 | AS20: 1.7726894 | AT20: 0.8173774 | AU20: 0.63439793 | AV20: 0.96111963 | AW20: 32.70281 | AX20: 4.4633686 | AY20: 5.084455 | AZ20: 5.2563668 | BA20: 7.8485616 | BB20: 167.55236 | BC20: 8.8344129 | BD20: 16.440477 | BE20: 17.683578 | BF20: 24.64074 | BG20: 7.1281505 | BH20: 0.93159546 | BI20: 0.71325652 | BJ20: 1.0130132 | BK20: 1.3335058 | BL20: 7.0599115 | BM20: 0.74781402 | BN20: 2.4830975 | BO20: 1.8336419 | BP20: 3.4571201 | BQ20: 24.930589 | BR20: 3.0650617 | BS20: 4.2212683 | BT20: 3.1230908 | BU20: 4.9459634 | BV20: 16.88358 | BW20: 24.726738 | BX20: -7.4583313 | BY20: 0.45334796 | CA20: 0.22590377 | CB20: 5.3117301 | CC20: 20.247814 | CD20: 14.514714
A21: 39722 | B21: 0 | C21: 18.468258 | D21: -2.1795617 | E21: 2.5216631 | F21: 0.14071031 | G21: 1.8794571 | H21: 27.44976 | I21: 2.4093368 | J21: 3.6037768 | K21: 3.2754075 | L21: 5.6169663 | M21: 22.710833 | N21: 24.868203 | O21: 27.140122 | P21: 55.2 | Q21: 1.8 | R21: 0.05 | S21: 0.08125 | T21: -0.25416667 | U21: 3.8779545 | V21: 0.36410583 | W21: 0.56215211 | X21: 0.53340583 | Z21: 9.2428739 | AA21: 1.4513064 | AB21: 1.3880612 | AC21: 1.6743493 | AD21: 2.4410106 | AE21: 32.503341 | AF21: 30.658366 | AG21: 35.432958 | AH21: 0.47287937 | AI21: -0.029471239 | AJ21: 0.011937509 | AK21: 0.029035737 | AL21: 0.035929424 | AM21: -1.4269295 | AN21: -0.99246498 | AO21: 0.002591767 | AP21: 0.32016702 | AQ21: -0.45312377 | AR21: 9.9043302 | AS21: 1.5504262 | AT21: 0.86772572 | AU21: 1.2513263 | AV21: 1.6338565 | AW21: 33.959309 | AX21: 4.6925336 | AY21: 4.9658423 | AZ21: 5.2417516 | BA21: 7.9400993 | BB21: 174.0307 | BC21: 19.853007 | BD21: 18.444949 | BE21: 20.051797 | BF21: 27.972142 | BG21: 6.3720342 | BH21: 0.083761228 | BI21: 0.29603324 | BJ21: 0.078582728 | BK21: 0.41255927 | BL21: 8.1558944 | BM21: 1.5009638 | BN21: 2.2009197 | BO21: 2.3088505 | BP21: 4.0193136 | BQ21: 24.436185 | BR21: 0.0020417354 | BS21: 3.4188245 | BT21: 1.5733695 | BU21: 3.7804385 | BV21: 26.903725 | BW21: 27.392931 | BX21: -2.8222457 | BY21: 12.338076 | BZ21: 22.758411 | CA21: -4.006757 | CB21: -8.9690121 | CC21: 17.219071 | CD21: 5.2200996
A22: 39814 | B22: 1 | C22: 18.698334 | D22: -3.9551202 | E22: 2.3402799 | F22: -0.25962949 | G22: 1.6671816 | H22: 30.570673 | I22: 4.2797097 | J22: 4.3229288 | K22: 5.4953762 | L22: 7.8110766 | M22: 31.012043 | N22: 27.632132 | O22: 30.58691 | P22: 76.45 | Q22: 24.9 | R22: 8.325 | S22: 21.31875 | T22: 20.9 | U22: 4.3245341 | V22: 0.69690669 | W22: 0.67403121 | X22: 0.83944739 | Y22: 1.1625996 | Z22: 9.8879945 | AA22: 1.8774307 | AB22: 1.5344137 | AC22: 1.9724545 | AD22: 2.7081854 | AE22: 31.443085 | AF22: 28.660705 | AG22: 33.315207 | AH22: 0.52909298 | AI22: 0.027833288 | AJ22: 0.065790324 | AK22: 0.082264972 | AL22: 0.089880474 | AM22: -0.44069082 | AN22: 0.28090569 | AO22: 1.172732 | AP22: 1.3057578 | AQ22: 0.70078309 | AR22: 14.716939 | AS22: 3.9903005 | AT22: 3.2990297 | AU22: 5.8470038 | AV22: 6.2241007 | AW22: 38.439433 | AX22: 8.4570293 | AY22: 6.0355273 | AZ22: 8.4804154 | BA22: 11.172789 | BB22: 189.23989 | BC22: 39.155641 | BD22: 19.783193 | BE22: 30.649754 | BF22: 39.236037 | BG22: 5.7947277 | BH22: -0.72437104 | BI22: 0.066560592 | BJ22: -0.57273206 | BK22: -0.26386635 | BL22: 11.020645 | BM22: 5.153043 | BN22: 2.8337564 | BO22: 4.6233707 | BP22: 6.0779451 | BQ22: 26.764264 | BR22: -0.4136169 | BS22: 3.8159761 | BT22: 3.0467426 | BU22: 5.4457957 | BV22: 43.114196 | BW22: 36.479054 | BX22: 6.9121116 | BY22: 29.254108 | BZ22: 32.965722 | CA22: -3.9450134 | CB22: -12.707372 | CC22: 13.822199 | CD22: 0.97707535
A23: 39904 | B23: 0 | C23: 19.182676 | D23: -2.2933947 | E23: 1.5040567 | F23: -0.36035741 | G23: 1.6970927 | H23: 33.206088 | I23: 6.561714 | J23: 5.082198 | K23: 7.0500591 | L23: 9.2802052 | M23: 33.577862 | N23: 25.572552 | O23: 29.483448 | P23: 93.2 | Q23: 41.8 | R23: 15.875 | S23: 35.9875 | T23: 35.9625 | U23: 4.7664857 | V23: 1.0953121 | W23: 0.78812098 | X23: 1.1128912 | Y23: 1.4346786 | Z23: 10.36406 | AA23: 2.0738743 | AB23: 1.6442182 | AC23: 2.0649168 | AD23: 2.780375 | AE23: 28.084133 | AF23: 27.126494 | AG23: 31.39331 | AH23: 0.55903161 | AI23: 0.059726166 | AJ23: 0.091797431 | AK23: 0.095756018 | AL23: 0.11280263 | AM23: 1.0919179 | AN23: 2.593545 | AO23: 1.7960247 | AP23: 2.5451835 | AQ23: 2.337587 | AR23: 15.631417 | AS23: 5.5939189 | AT23: 4.1033056 | AU23: 5.9367246 | AV23: 6.567809 | AW23: 40.212605 | AX23: 8.5669856 | AY23: 6.3526005 | AZ23: 8.7447056 | BA23: 11.401671 | BB23: 193.146 | BC23: 35.216481 | BD23: 18.29543 | BE23: 29.61006 | BF23: 38.01322 | BG23: 5.9604112 | BH23: -0.91522534 | BI23: 0.031043725 | BJ23: -0.42368877 | BK23: -0.15987528 | BL23: 12.845886 | BM23: 6.8209978 | BN23: 3.5480755 | BO23: 5.7401732 | BP23: 7.0207165 | BQ23: 30.445963 | BR23: 3.7329297 | BS23: 4.6977302 | BT23: 5.774447 | BU23: 8.2447312 | BV23: 48.369317 | BW23: 39.561159 | BX23: 8.8384141 | BY23: 32.781201 | BZ23: 31.957262 | CA23: -6.6820011 | CB23: -11.931139 | CC23: 5.6061848 | CD23: -5.2154621 | CE23: 6.996315
A24: 39995 | B24: 0 | C24: 20.147829 | D24: 0.19997086 | E24: 0.93495887 | F24: 0.22878087 | G24: 2.1219595 | H24: 35.312668 | I24: 8.8636735 | J24: 5.775658 | K24: 7.8860893 | L24: 10.054282 | M24: 31.798425 | N24: 24.079359 | O24: 27.525566 | P24: 86.2 | Q24: 36.6 | R24: 13.775 | S24: 25.01875 | T24: 26.116667 | U24: 5.1690818 | V24: 1.5037128 | W24: 0.90553835 | X24: 1.3184571 | Y24: 1.6433799 | Z24: 10.604116 | AA24: 1.9287277 | AB24: 1.5925835 | AC24: 1.8939182 | AD24: 2.6071332 | AE24: 20.074578 | AF24: 24.808172 | AG24: 28.1025 | AH24: 0.68707515 | AI24: 0.2223259 | AJ24: 0.16297226 | AK24: 0.2008502 | AL24: 0.22825535 | AM24: 1.4387372 | AN24: 3.5862725 | AO24: 1.9459433 | AP24: 2.4429966 | AQ24: 2.6594828 | AR24: 17.938281 | AS24: 8.8552232 | AT24: 5.3139563 | AU24: 7.2177615 | AV24: 8.1945289 | AW24: 42.348551 | AX24: 9.6457408 | AY24: 7.0545547 | AZ24: 9.2925013 | BA24: 11.941409 | BB24: 203.02636 | BC24: 35.474 | BD24: 22.154206 | BE24: 34.916565 | BF24: 42.783092 | BG24: 6.1778416 | BH24: -0.95030896 | BI24: -0.0093567482 | BJ24: -0.21401931 | BK24: -0.0035269799 | BL24: 12.306031 | BM24: 5.2461193 | BN24: 2.9969666 | BO24: 4.313299 | BP24: 5.5649897 | BQ24: 35.596875 | BR24: 10.666286 | BS24: 6.8656739 | BT24: 9.750927 | BU24: 12.177126 | BV24: 42.766549 | BW24: 25.882969 | BX24: 25.304853 | BY24: 24.968829 | BZ24: 20.540493 | CA24: -10.381908 | CB24: -10.607812 | CC24: -2.6480409 | CD24: -10.316915 | CE24: 0.3446209
